Workbook
Name Slicer_City: #N/A
Name Slicer_Membership_Type: #N/A
Name Slicer_Referred: #N/A

Sheet sheet1
A1: Member_ID | B1: Full_Name | C1: Age | D1: Gender | E1: c | F1: Start_Date | G1: End_Date | H1: Monthly_Fee | I1: Attendance | J1: City | K1: Referred_By
A2: M001 | B2: Anay Shanker | C2: 59 | D2: Male | E2: Basic | F2: 45235 | G2: 45425 | H2: 800 | I2: 25 | J2: Bengaluru | K2: Hiran Shan
A3: M002 | B3: Parinaaz Shanker | C3: 27 | D3: Male | E3: Basic | F3: 45714 | G3: 45740 | H3: 800 | I3: 20 | J3: Pune | K3: Kiara Kakar
A4: M003 | B4: Aniruddh Batra | C4: 24 | D4: Male | E4: Standard | F4: 45191 | G4: 45371 | H4: 1200 | I4: 18 | J4: Hyderabad | K4: Jhanvi Chaudhary
A5: M004 | B5: Madhup Kapur | C5: 31 | D5: Female | E5: Standard | F5: 45479 | G5: 45587 | H5: 1200 | I5: 16 | J5: Hyderabad | K5: Tara Swaminathan
A6: M005 | B6: Rasha Kakar | C6: 19 | D6: Male | E6: Family | F6: 45286 | G6: 45501 | H6: 2500 | I6: 12 | J6: Bengaluru | K6: Madhav Singh
A7: M006 | B7: Ehsaan Batra | C7: 40 | D7: Male | E7: Basic | F7: 45317 | G7: 45392 | H7: 800 | I7: 14 | J7: Mumbai | K7: Shray Ramakrishnan
A8: M007 | B8: Zara Bains | C8: 41 | D8: Female | E8: Basic | F8: 45588 | G8: 45677 | H8: 800 | I8: 25 | J8: Pune
A9: M008 | B9: Uthkarsh Baral | C9: 43 | D9: Male | E9: Premium | F9: 45450 | G9: 45563 | H9: 1800 | I9: 28 | J9: Kolkata
A10: M009 | B10: Kashvi Char | C10: 42 | D10: Male | E10: Basic | F10: 45569 | G10: 45582 | H10: 800 | I10: 3 | J10: Kolkata | K10: Nitara Comar
A11: M010 | B11: Dhanush Varma | C11: 37 | D11: Male | E11: Standard | F11: 45202 | G11: 45280 | H11: 1200 | I11: 29 | J11: Mumbai | K11: Ranbir Karan
A12: M011 | B12: Ishaan Goyal | C12: 48 | D12: Female | E12: Standard | F12: 45297 | G12: 45459 | H12: 1200 | I12: 13 | J12: Bengaluru | K12: Rati Sanghvi
A13: M012 | B13: Mahika Ravi | C13: 36 | D13: Male | E13: Standard | F13: 45154 | G13: 45568 | H13: 1200 | I13: 19 | J13: Kolkata | K13: Ishaan Kashyap
A14: M013 | B14: Purab Reddy | C14: 48 | D14: Female | E14: Premium | F14: 45556 | G14: 45641 | H14: 1800 | I14: 22 | J14: Kolkata
A15: M014 | B15: Tiya Soni | C15: 39 | D15: Male | E15: Standard | F15: 45065 | G15: 45242 | H15: 1200 | I15: 28 | J15: Mumbai
A16: M015 | B16: Zara Dugar | C16: 44 | D16: Female | E16: Basic | F16: 45333 | G16: 45540 | H16: 800 | I16: 8 | J16: Hyderabad
A17: M016 | B17: Lakshit Mander | C17: 39 | D17: Male | E17: Family | F17: 45702 | G17: 45732 | H17: 2500 | I17: 14 | J17: Kolkata
A18: M017 | B18: Neysa Krish | C18: 35 | D18: Male | E18: Standard | F18: 45329 | G18: 45685 | H18: 1200 | I18: 25 | J18: Hyderabad
A19: M018 | B19: Prerak Boase | C19: 56 | D19: Female | E19: Family | F19: 45213 | G19: 45649 | H19: 2500 | I19: 13 | J19: Delhi
A20: M019 | B20: Siya Master | C20: 27 | D20: Female | E20: Basic | F20: 45354 | G20: 45664 | H20: 800 | I20: 26 | J20: Mumbai
A21: M020 | B21: Madhup Biswas | C21: 28 | D21: Male | E21: Family | F21: 45417 | G21: 45608 | H21: 2500 | I21: 21 | J21: Mumbai | K21: Tanya Bajwa
A22: M021 | B22: Indrans Ratti | C22: 57 | D22: Female | E22: Premium | F22: 45146 | G22: 45674 | H22: 1800 | I22: 19 | J22: Mumbai
A23: M022 | B23: Kimaya Balay | C23: 26 | D23: Female | E23: Premium | F23: 45320 | G23: 45616 | H23: 1800 | I23: 5 | J23: Bengaluru
A24: M023 | B24: Eva Dass | C24: 48 | D24: Male | E24: Premium | F24: 45451 | G24: 45455 | H24: 1800 | I24: 18 | J24: Delhi
A25: M024 | B25: Pihu Wali | C25: 25 | D25: Female | E25: Standard | F25: 45439 | G25: 45730 | H25: 1200 | I25: 6 | J25: Bengaluru
A26: M025 | B26: Tiya Rege | C26: 53 | D26: Male | E26: Premium | F26: 45286 | G26: 45372 | H26: 1800 | I26: 17 | J26: Mumbai | K26: Adira Brar
A27: M026 | B27: Aarav Sen | C27: 42 | D27: Female | E27: Standard | F27: 45702 | G27: 45727 | H27: 1200 | I27: 3 | J27: Delhi
A28: M027 | B28: Dishani Bera | C28: 24 | D28: Male | E28: Family | F28: 45698 | G28: 45726 | H28: 2500 | I28: 28 | J28: Mumbai
A29: M028 | B29: Indrans Grover | C29: 53 | D29: Male | E29: Standard | F29: 45614 | G29: 45645 | H29: 1200 | I29: 23 | J29: Pune
A30: M029 | B30: Kismat Edwin | C30: 29 | D30: Female | E30: Family | F30: 45401 | G30: 45408 | H30: 2500 | I30: 8 | J30: Hyderabad
A31: M030 | B31: Taran Vyas | C31: 31 | D31: Female | E31: Family | F31: 45667 | G31: 45745 | H31: 2500 | I31: 23 | J31: Kolkata | K31: Nakul Balakrishnan
A32: M031 | B32: Jiya Baral | C32: 52 | D32: Female | E32: Basic | F32: 45088 | G32: 45656 | H32: 800 | I32: 9 | J32: Delhi | K32: Darshit Sidhu
A33: M032 | B33: Gokul Sahni | C33: 20 | D33: Male | E33: Standard | F33: 45391 | G33: 45604 | H33: 1200 | I33: 2 | J33: Mumbai
A34: M033 | B34: Prerak Lalla | C34: 22 | D34: Male | E34: Basic | F34: 45699 | G34: 45740 | H34: 800 | I34: 30 | J34: Mumbai
A35: M034 | B35: Hrishita Shroff | C35: 23 | D35: Male | E35: Premium | F35: 45588 | G35: 45721 | H35: 1800 | I35: 23 | J35: Pune | K35: Riya Dugal
A36: M035 | B36: Oorja Sachar | C36: 27 | D36: Female | E36: Standard | F36: 45312 | G36: 45652 | H36: 1200 | I36: 27 | J36: Pune

Sheet Question.1
A2: Start_date | B2: End_date | C2: Membership_Duration_Month | E2: Ans:-
A3: 45235 | B3: 45425 | C3: =(B3-A3)/30 -> 6.3333333 | E3: Here we apply formula for
A4: 45714 | B4: 45740 | C4: =(B4-A4)/30 -> 0.86666667 | E4: membership duration months
A5: 45191 | B5: 45371 | C5: =(B5-A5)/30 -> 6 | E5: formula:-(start_date-End_date)/30
A6: 45479 | B6: 45587 | C6: =(B6-A6)/30 -> 3.6
A7: 45286 | B7: 45501 | C7: =(B7-A7)/30 -> 7.1666667
A8: 45317 | B8: 45392 | C8: =(B8-A8)/30 -> 2.5
A9: 45588 | B9: 45677 | C9: =(B9-A9)/30 -> 2.9666667
A10: 45450 | B10: 45563 | C10: =(B10-A10)/30 -> 3.7666667
A11: 45569 | B11: 45582 | C11: =(B11-A11)/30 -> 0.43333333
A12: 45202 | B12: 45280 | C12: =(B12-A12)/30 -> 2.6
A13: 45297 | B13: 45459 | C13: =(B13-A13)/30 -> 5.4
A14: 45154 | B14: 45568 | C14: =(B14-A14)/30 -> 13.8
A15: 45556 | B15: 45641 | C15: =(B15-A15)/30 -> 2.8333333
A16: 45065 | B16: 45242 | C16: =(B16-A16)/30 -> 5.9
A17: 45333 | B17: 45540 | C17: =(B17-A17)/30 -> 6.9
... A37: 45312 | B37: 45652 | C37: =(B37-A37)/30 -> 11.333333

Sheet Question.2
A1: Full_name | B1: Referred_by | C1: Monthly_Fee | D1: Referred_Status | G1: Pivot Table
A2: Anay Shanker | B2: Hiran Shan | C2: 800 | D2: {=IF(B2:B36="","No","yes")} -> yes
A3: Parinaaz Shanker | B3: Kiara Kakar | C3: 800 | D3: yes | G3: Row Labels | H3: Average of Monthly_Fee
A4: Aniruddh Batra | B4: Jhanvi Chaudhary | C4: 1200 | D4: yes | G4: No | H4: 1530
A5: Madhup Kapur | B5: Tara Swaminathan | C5: 1200 | D5: yes | G5: yes | H5: 1406.6667
A6: Rasha Kakar | B6: Madhav Singh | C6: 2500 | D6: yes | G6: Grand Total | H6: 1477.1429
A7: Ehsaan Batra | B7: Shray Ramakrishnan | C7: 800 | D7: yes
A8: Zara Bains | C8: 800 | D8: No
A9: Uthkarsh Baral | C9: 1800 | D9: No | G9: ##we create a new column as referred status
A10: Kashvi Char | B10: Nitara Comar | C10: 800 | D10: yes | G10: formula-(Referred_by="","yes","no")
A11: Dhanush Varma | B11: Ranbir Karan | C11: 1200 | D11: yes
A12: Ishaan Goyal | B12: Rati Sanghvi | C12: 1200 | D12: yes
A13: Mahika Ravi | B13: Ishaan Kashyap | C13: 1200 | D13: yes
A14: Purab Reddy | C14: 1800 | D14: No
A15: Tiya Soni | C15: 1200 | D15: No
A16: Zara Dugar | C16: 800 | D16: No
A17: Lakshit Mander | C17: 2500 | D17: No
A18: Neysa Krish | C18: 1200 | D18: No
A19: Prerak Boase | C19: 2500 | D19: No
A20: Siya Master | C20: 800 | D20: No
A21: Madhup Biswas | B21: Tanya Bajwa | C21: 2500 | D21: yes
A22: Indrans Ratti | C22: 1800 | D22: No
A23: Kimaya Balay | C23: 1800 | D23: No
A24: Eva Dass | C24: 1800 | D24: No
A25: Pihu Wali | C25: 1200 | D25: No
A26: Tiya Rege | B26: Adira Brar | C26: 1800 | D26: yes
A27: Aarav Sen | C27: 1200 | D27: No
A28: Dishani Bera | C28: 2500 | D28: No
A29: Indrans Grover | C29: 1200 | D29: No
A30: Kismat Edwin | C30: 2500 | D30: No
A31: Taran Vyas | B31: Nakul Balakrishnan | C31: 2500 | D31: yes
A32: Jiya Baral | B32: Darshit Sidhu | C32: 800 | D32: yes
A33: Gokul Sahni | C33: 1200 | D33: No
A34: Prerak Lalla | C34: 800 | D34: No
A35: Hrishita Shroff | B35: Riya Dugal | C35: 1800 | D35: yes
A36: Oorja Sachar | C36: 1200 | D36: No

Sheet Question.3
A1: Monthly_Fee | B1: Start_Date | C1: End_date | D1: Membership_Type | E1: City | F1: Membership_Duration_months | G1: Total_revenue | J1: Pivot Table For Membership Type
A2: 800 | B2: 45235 | C2: 45425 | D2: Basic | E2: Bengaluru | F2: =(C2-B2)/30 -> 6.3333333 | G2: =A2*F2 -> 5066.6667 | J2: Row Labels | K2: Sum of Total_revenue | M2: #we create a new column total_revenue by using formula :-monthly_fee*membership duration month
A3: 800 | B3: 45714 | C3: 45740 | D3: Basic | E3: Pune | F3: =(C3-B3)/30 -> 0.86666667 | G3: =A3*F3 -> 693.33333 | J3: Basic | K3: 40506.667
A4: 1200 | B4: 45191 | C4: 45371 | D4: Standard | E4: Hyderabad | F4: =(C4-B4)/30 -> 6 | G4: =A4*F4 -> 7200 | J4: Family | K4: 82083.333
A5: 1200 | B5: 45479 | C5: 45587 | D5: Standard | E5: Hyderabad | F5: =(C5-B5)/30 -> 3.6 | G5: =A5*F5 -> 4320 | J5: Premium | K5: 74700
A6: 2500 | B6: 45286 | C6: 45501 | D6: Family | E6: Bengaluru | F6: =(C6-B6)/30 -> 7.1666667 | G6: =A6*F6 -> 17916.667 | J6: Standard | K6: 95000
A7: 800 | B7: 45317 | C7: 45392 | D7: Basic | E7: Mumbai | F7: =(C7-B7)/30 -> 2.5 | G7: =A7*F7 -> 2000 | J7: Grand Total | K7: 292290
A8: 800 | B8: 45588 | C8: 45677 | D8: Basic | E8: Pune | F8: =(C8-B8)/30 -> 2.9666667 | G8: =A8*F8 -> 2373.3333
A9: 1800 | B9: 45450 | C9: 45563 | D9: Premium | E9: Kolkata | F9: =(C9-B9)/30 -> 3.7666667 | G9: =A9*F9 -> 6780 | J9: Pivot Table citywise
A10: 800 | B10: 45569 | C10: 45582 | D10: Basic | E10: Kolkata | F10: =(C10-B10)/30 -> 0.43333333 | G10: =A10*F10 -> 346.66667 | J10: Row Labels | K10: Sum of Total_revenue
A11: 1200 | B11: 45202 | C11: 45280 | D11: Standard | E11: Mumbai | F11: =(C11-B11)/30 -> 2.6 | G11: =A11*F11 -> 3120 | J11: Bengaluru | K11: 58863.333
A12: 1200 | B12: 45297 | C12: 45459 | D12: Standard | E12: Bengaluru | F12: =(C12-B12)/30 -> 5.4 | G12: =A12*F12 -> 6480 | J12: Delhi | K12: 52720
A13: 1200 | B13: 45154 | C13: 45568 | D13: Standard | E13: Kolkata | F13: =(C13-B13)/30 -> 13.8 | G13: =A13*F13 -> 16560 | J13: Hyderabad | K13: 31863.333
A14: 1800 | B14: 45556 | C14: 45641 | D14: Premium | E14: Kolkata | F14: =(C14-B14)/30 -> 2.8333333 | G14: =A14*F14 -> 5100 | J14: Kolkata | K14: 37786.667
A15: 1200 | B15: 45065 | C15: 45242 | D15: Standard | E15: Mumbai | F15: =(C15-B15)/30 -> 5.9 | G15: =A15*F15 -> 7080 | J15: Mumbai | K15: 85170
A16: 800 | B16: 45333 | C16: 45540 | D16: Basic | E16: Hyderabad | F16: =(C16-B16)/30 -> 6.9 | G16: =A16*F16 -> 5520 | J16: Pune | K16: 25886.667
A17: 2500 | B17: 45702 | C17: 45732 | D17: Family | E17: Kolkata | F17: =(C17-B17)/30 -> 1 | G17: =A17*F17 -> 2500 | J17: Grand Total | K17: 292290
A18: 1200 | B18: 45329 | C18: 45685 | D18: Standard | E18: Hyderabad | F18: =(C18-B18)/30 -> 11.866667 | G18: =A18*F18 -> 14240
A19: 2500 | B19: 45213 | C19: 45649 | D19: Family | E19: Delhi | F19: =(C19-B19)/30 -> 14.533333 | G19: =A19*F19 -> 36333.333
A20: 800 | B20: 45354 | C20: 45664 | D20: Basic | E20: Mumbai | F20: =(C20-B20)/30 -> 10.333333 | G20: =A20*F20 -> 8266.6667
A21: 2500 | B21: 45417 | C21: 45608 | D21: Family | E21: Mumbai | F21: =(C21-B21)/30 -> 6.3666667 | G21: =A21*F21 -> 15916.667
A22: 1800 | B22: 45146 | C22: 45674 | D22: Premium | E22: Mumbai | F22: =(C22-B22)/30 -> 17.6 | G22: =A22*F22 -> 31680
A23: 1800 | B23: 45320 | C23: 45616 | D23: Premium | E23: Bengaluru | F23: =(C23-B23)/30 -> 9.8666667 | G23: =A23*F23 -> 17760
A24: 1800 | B24: 45451 | C24: 45455 | D24: Premium | E24: Delhi | F24: =(C24-B24)/30 -> 0.13333333 | G24: =A24*F24 -> 240
A25: 1200 | B25: 45439 | C25: 45730 | D25: Standard | E25: Bengaluru | F25: =(C25-B25)/30 -> 9.7 | G25: =A25*F25 -> 11640
A26: 1800 | B26: 45286 | C26: 45372 | D26: Premium | E26: Mumbai | F26: =(C26-B26)/30 -> 2.8666667 | G26: =A26*F26 -> 5160
A27: 1200 | B27: 45702 | C27: 45727 | D27: Standard | E27: Delhi | F27: =(C27-B27)/30 -> 0.83333333 | G27: =A27*F27 -> 1000
A28: 2500 | B28: 45698 | C28: 45726 | D28: Family | E28: Mumbai | F28: =(C28-B28)/30 -> 0.93333333 | G28: =A28*F28 -> 2333.3333
A29: 1200 | B29: 45614 | C29: 45645 | D29: Standard | E29: Pune | F29: =(C29-B29)/30 -> 1.0333333 | G29: =A29*F29 -> 1240
... A36: 1200 | B36: 45312 | C36: 45652 | D36: Standard | E36: Pune | F36: =(C36-B36)/30 -> 11.333333 | G36: =A36*F36 -> 13600

Sheet Question.4
A1: Full_Name | B1: Attendance | C1: Membership_Duration_month | D1: Low_Engagement_Flag
A2: Anay Shanker | B2: 25 | C2: =(sheet1!G2-sheet1!F2)/30 -> 6.3333333 | D2: =IF(AND(B2<8,C2>=6),"yes","no") -> no | E2: #we use Conditional Formatting to highlight
A3: Parinaaz Shanker | B3: 20 | C3: =(sheet1!G3-sheet1!F3)/30 -> 0.86666667 | D3: =IF(AND(B3<8,C3>=6),"yes","no") -> no | E3: member with attendance<8 and membership duration month>=6
A4: Aniruddh Batra | B4: 18 | C4: =(sheet1!G4-sheet1!F4)/30 -> 6 | D4: =IF(AND(B4<8,C4>=6),"yes","no") -> no | E4: formula for low engagement flag :if(And(attendance<8,membership duration month>=6 | M4: ),"yes","no")
A5: Madhup Kapur | B5: 16 | C5: =(sheet1!G5-sheet1!F5)/30 -> 3.6 | D5: =IF(AND(B5<8,C5>=6),"yes","no") -> no
A6: Rasha Kakar | B6: 12 | C6: =(sheet1!G6-sheet1!F6)/30 -> 7.1666667 | D6: =IF(AND(B6<8,C6>=6),"yes","no") -> no
A7: Ehsaan Batra | B7: 14 | C7: =(sheet1!G7-sheet1!F7)/30 -> 2.5 | D7: =IF(AND(B7<8,C7>=6),"yes","no") -> no
A8: Zara Bains | B8: 25 | C8: =(sheet1!G8-sheet1!F8)/30 -> 2.9666667 | D8: =IF(AND(B8<8,C8>=6),"yes","no") -> no
A9: Uthkarsh Baral | B9: 28 | C9: =(sheet1!G9-sheet1!F9)/30 -> 3.7666667 | D9: =IF(AND(B9<8,C9>=6),"yes","no") -> no
A10: Kashvi Char | B10: 3 | C10: =(sheet1!G10-sheet1!F10)/30 -> 0.43333333 | D10: =IF(AND(B10<8,C10>=6),"yes","no") -> no
A11: Dhanush Varma | B11: 29 | C11: =(sheet1!G11-sheet1!F11)/30 -> 2.6 | D11: =IF(AND(B11<8,C11>=6),"yes","no") -> no
A12: Ishaan Goyal | B12: 13 | C12: =(sheet1!G12-sheet1!F12)/30 -> 5.4 | D12: =IF(AND(B12<8,C12>=6),"yes","no") -> no
A13: Mahika Ravi | B13: 19 | C13: =(sheet1!G13-sheet1!F13)/30 -> 13.8 | D13: =IF(AND(B13<8,C13>=6),"yes","no") -> no
A14: Purab Reddy | B14: 22 | C14: =(sheet1!G14-sheet1!F14)/30 -> 2.8333333 | D14: =IF(AND(B14<8,C14>=6),"yes","no") -> no
A15: Tiya Soni | B15: 28 | C15: =(sheet1!G15-sheet1!F15)/30 -> 5.9 | D15: =IF(AND(B15<8,C15>=6),"yes","no") -> no
A16: Zara Dugar | B16: 8 | C16: =(sheet1!G16-sheet1!F16)/30 -> 6.9 | D16: =IF(AND(B16<8,C16>=6),"yes","no") -> no
... A36: Oorja Sachar | B36: 27 | C36: =(sheet1!G36-sheet1!F36)/30 -> 11.333333 | D36: =IF(AND(B36<8,C36>=6),"yes","no") -> no

Sheet Question.5
A1: Member_ID | B1: City | C1: Membership_Type | D1: Monthly_Fee | E1: Total_Revenue | F1: Referred
A2: =SUBSTITUTE(sheet1!A2,"M","")+0 -> 1 | B2: Bengaluru | C2: Basic | D2: 800 | E2: =D2*Question.1!C3 -> 5066.6667 | F2: =IF(TRIM(sheet1!K2)<> "","yes","no") -> yes
A3: =SUBSTITUTE(sheet1!A3,"M","")+0 -> 2 | B3: Pune | C3: Basic | D3: 800 | E3: =D3*Question.1!C4 -> 693.33333 | F3: =IF(TRIM(sheet1!K3)<>"","yes","no") -> yes | H3: c | I3: Sum of Total_Revenue | J3: Average Revenue
A4: =SUBSTITUTE(sheet1!A4,"M","")+0 -> 3 | B4: Hyderabad | C4: Standard | D4: 1200 | E4: =D4*Question.1!C5 -> 7200 | F4: =IF(TRIM(sheet1!K4)<> "","yes","no") -> yes | H4: Bengaluru | I4: 58863.333 | J4: 11772.667
A5: =SUBSTITUTE(sheet1!A5,"M","")+0 -> 4 | B5: Hyderabad | C5: Standard | D5: 1200 | E5: =D5*Question.1!C6 -> 4320 | F5: =IF(TRIM(sheet1!K5)<>"","yes","no") -> yes | H5: no | I5: 29400 | J5: 14700
A6: =SUBSTITUTE(sheet1!A6,"M","")+0 -> 5 | B6: Bengaluru | C6: Family | D6: 2500 | E6: =D6*Question.1!C7 -> 17916.667 | F6: =IF(TRIM(sheet1!K6)<> "","yes","no") -> yes | H6: Premium | I6: 17760 | J6: 17760
A7: =SUBSTITUTE(sheet1!A7,"M","")+0 -> 6 | B7: Mumbai | C7: Basic | D7: 800 | E7: =D7*Question.1!C8 -> 2000 | F7: =IF(TRIM(sheet1!K7)<>"","yes","no") -> yes | H7: Standard | I7: 11640 | J7: 11640
A8: =SUBSTITUTE(sheet1!A8,"M","")+0 -> 7 | B8: Pune | C8: Basic | D8: 800 | E8: =D8*Question.1!C9 -> 2373.3333 | F8: =IF(TRIM(sheet1!K8)<> "","yes","no") -> no | H8: yes | I8: 29463.333 | J8: 9821.1111
A9: =SUBSTITUTE(sheet1!A9,"M","")+0 -> 8 | B9: Kolkata | C9: Premium | D9: 1800 | E9: =D9*Question.1!C10 -> 6780 | F9: =IF(TRIM(sheet1!K9)<>"","yes","no") -> no | H9: Basic | I9: 5066.6667 | J9: 5066.6667
A10: =SUBSTITUTE(sheet1!A10,"M","")+0 -> 9 | B10: Kolkata | C10: Basic | D10: 800 | E10: =D10*Question.1!C11 -> 346.66667 | F10: =IF(TRIM(sheet1!K10)<> "","yes","no") -> yes | H10: Family | I10: 17916.667 | J10: 17916.667
A11: =SUBSTITUTE(sheet1!A11,"M","")+0 -> 10 | B11: Mumbai | C11: Standard | D11: 1200 | E11: =D11*Question.1!C12 -> 3120 | F11: =IF(TRIM(sheet1!K11)<>"","yes","no") -> yes | H11: Standard | I11: 6480 | J11: 6480
A12: =SUBSTITUTE(sheet1!A12,"M","")+0 -> 11 | B12: Bengaluru | C12: Standard | D12: 1200 | E12: =D12*Question.1!C13 -> 6480 | F12: =IF(TRIM(sheet1!K12)<> "","yes","no") -> yes | H12: Delhi | I12: 52720 | J12: 13180
A13: =SUBSTITUTE(sheet1!A13,"M","")+0 -> 12 | B13: Kolkata | C13: Standard | D13: 1200 | E13: =D13*Question.1!C14 -> 16560 | F13: =IF(TRIM(sheet1!K13)<>"","yes","no") -> yes | H13: no | I13: 37573.333 | J13: 12524.444
A14: =SUBSTITUTE(sheet1!A14,"M","")+0 -> 13 | B14: Kolkata | C14: Premium | D14: 1800 | E14: =D14*Question.1!C15 -> 5100 | F14: =IF(TRIM(sheet1!K14)<> "","yes","no") -> no | H14: Family | I14: 36333.333 | J14: 36333.333
A15: =SUBSTITUTE(sheet1!A15,"M","")+0 -> 14 | B15: Mumbai | C15: Standard | D15: 1200 | E15: =D15*Question.1!C16 -> 7080 | F15: =IF(TRIM(sheet1!K15)<>"","yes","no") -> no | H15: Premium | I15: 240 | J15: 240
A16: =SUBSTITUTE(sheet1!A16,"M","")+0 -> 15 | B16: Hyderabad | C16: Basic | D16: 800 | E16: =D16*Question.1!C17 -> 5520 | F16: =IF(TRIM(sheet1!K16)<> "","yes","no") -> no | H16: Standard | I16: 1000 | J16: 1000
A17: =SUBSTITUTE(sheet1!A17,"M","")+0 -> 16 | B17: Kolkata | C17: Family | D17: 2500 | E17: =D17*Question.1!C18 -> 2500 | F17: =IF(TRIM(sheet1!K17)<>"","yes","no") -> no | H17: yes | I17: 15146.667 | J17: 15146.667
A18: =SUBSTITUTE(sheet1!A18,"M","")+0 -> 17 | B18: Hyderabad | C18: Standard | D18: 1200 | E18: =D18*Question.1!C19 -> 14240 | F18: =IF(TRIM(sheet1!K18)<> "","yes","no") -> no | H18: Basic | I18: 15146.667 | J18: 15146.667
A19: =SUBSTITUTE(sheet1!A19,"M","")+0 -> 18 | B19: Delhi | C19: Family | D19: 2500 | E19: =D19*Question.1!C20 -> 36333.333 | F19: =IF(TRIM(sheet1!K19)<>"","yes","no") -> no | H19: Hyderabad | I19: 31863.333 | J19: 6372.6667
A20: =SUBSTITUTE(sheet1!A20,"M","")+0 -> 19 | B20: Mumbai | C20: Basic | D20: 800 | E20: =D20*Question.1!C21 -> 8266.6667 | F20: =IF(TRIM(sheet1!K20)<> "","yes","no") -> no | H20: no | I20: 20343.333 | J20: 6781.1111
A21: =SUBSTITUTE(sheet1!A21,"M","")+0 -> 20 | B21: Mumbai | C21: Family | D21: 2500 | E21: =D21*Question.1!C22 -> 15916.667 | F21: =IF(TRIM(sheet1!K21)<>"","yes","no") -> yes | H21: Basic | I21: 5520 | J21: 5520
A22: =SUBSTITUTE(sheet1!A22,"M","")+0 -> 21 | B22: Mumbai | C22: Premium | D22: 1800 | E22: =D22*Question.1!C23 -> 31680 | F22: =IF(TRIM(sheet1!K22)<> "","yes","no") -> no | H22: Family | I22: 583.33333 | J22: 583.33333
A23: =SUBSTITUTE(sheet1!A23,"M","")+0 -> 22 | B23: Bengaluru | C23: Premium | D23: 1800 | E23: =D23*Question.1!C24 -> 17760 | F23: =IF(TRIM(sheet1!K23)<>"","yes","no") -> no | H23: Standard | I23: 14240 | J23: 14240
A24: =SUBSTITUTE(sheet1!A24,"M","")+0 -> 23 | B24: Delhi | C24: Premium | D24: 1800 | E24: =D24*Question.1!C25 -> 240 | F24: =IF(TRIM(sheet1!K24)<> "","yes","no") -> no | H24: yes | I24: 11520 | J24: 5760
A25: =SUBSTITUTE(sheet1!A25,"M","")+0 -> 24 | B25: Bengaluru | C25: Standard | D25: 1200 | E25: =D25*Question.1!C26 -> 11640 | F25: =IF(TRIM(sheet1!K25)<>"","yes","no") -> no | H25: Standard | I25: 11520 | J25: 5760
A26: =SUBSTITUTE(sheet1!A26,"M","")+0 -> 25 | B26: Mumbai | C26: Premium | D26: 1800 | E26: =D26*Question.1!C27 -> 5160 | F26: =IF(TRIM(sheet1!K26)<> "","yes","no") -> yes | H26: Kolkata | I26: 37786.667 | J26: 6297.7778
A27: =SUBSTITUTE(sheet1!A27,"M","")+0 -> 26 | B27: Delhi | C27: Standard | D27: 1200 | E27: =D27*Question.1!C28 -> 1000 | F27: =IF(TRIM(sheet1!K27)<>"","yes","no") -> no | H27: no | I27: 14380 | J27: 4793.3333
A28: =SUBSTITUTE(sheet1!A28,"M","")+0 -> 27 | B28: Mumbai | C28: Family | D28: 2500 | E28: =D28*Question.1!C29 -> 2333.3333 | F28: =IF(TRIM(sheet1!K28)<> "","yes","no") -> no | H28: Family | I28: 2500 | J28: 2500
A29: =SUBSTITUTE(sheet1!A29,"M","")+0 -> 28 | B29: Pune | C29: Standard | D29: 1200 | E29: =D29*Question.1!C30 -> 1240 | F29: =IF(TRIM(sheet1!K29)<>"","yes","no") -> no | H29: Premium | I29: 11880 | J29: 5940
A30: =SUBSTITUTE(sheet1!A30,"M","")+0 -> 29 | B30: Hyderabad | C30: Family | D30: 2500 | E30: =D30*Question.1!C31 -> 583.33333 | F30: =IF(TRIM(sheet1!K30)<> "","yes","no") -> no | H30: yes | I30: 23406.667 | J30: 7802.2222
A31: =SUBSTITUTE(sheet1!A31,"M","")+0 -> 30 | B31: Kolkata | C31: Family | D31: 2500 | E31: =D31*Question.1!C32 -> 6500 | F31: =IF(TRIM(sheet1!K31)<>"","yes","no") -> yes | H31: Basic | I31: 346.66667 | J31: 346.66667
A32: =SUBSTITUTE(sheet1!A32,"M","")+0 -> 31 | B32: Delhi | C32: Basic | D32: 800 | E32: =D32*Question.1!C33 -> 15146.667 | F32: =IF(TRIM(sheet1!K32)<> "","yes","no") -> yes | H32: Family | I32: 6500 | J32: 6500
A33: =SUBSTITUTE(sheet1!A33,"M","")+0 -> 32 | B33: Mumbai | C33: Standard | D33: 1200 | E33: =D33*Question.1!C34 -> 8520 | F33: =IF(TRIM(sheet1!K33)<>"","yes","no") -> no | H33: Standard | I33: 16560 | J33: 16560
A34: =SUBSTITUTE(sheet1!A34,"M","")+0 -> 33 | B34: Mumbai | C34: Basic | D34: 800 | E34: =D34*Question.1!C35 -> 1093.3333 | F34: =IF(TRIM(sheet1!K34)<> "","yes","no") -> no | H34: Mumbai | I34: 85170 | J34: 8517
A35: =SUBSTITUTE(sheet1!A35,"M","")+0 -> 34 | B35: Pune | C35: Premium | D35: 1800 | E35: =D35*Question.1!C36 -> 7980 | F35: =IF(TRIM(sheet1!K35)<>"","yes","no") -> yes | H35: no | I35: 58973.333 | J35: 9828.8889
A36: =SUBSTITUTE(sheet1!A36,"M","")+0 -> 35 | B36: Pune | C36: Standard | D36: 1200 | E36: =D36*Question.1!C37 -> 13600 | F36: =IF(TRIM(sheet1!K36)<> "","yes","no") -> no | H36: Basic | I36: 9360 | J36: 4680
H37: Family | I37: 2333.3333 | J37: 2333.3333
H38: Premium | I38: 31680 | J38: 31680
H39: Standard | I39: 15600 | J39: 7800
H40: yes | I40: 26196.667 | J40: 6549.1667
...

Sheet Dashboard
C6: Row Labels | D6: Sum of Total_Revenue | E6: Average Revenue
C7: Bengaluru | D7: 58863.333 | E7: 11772.667
C8: no | D8: 29400 | E8: 14700
C9: Premium | D9: 17760 | E9: 17760
C10: Standard | D10: 11640 | E10: 11640
C11: yes | D11: 29463.333 | E11: 9821.1111
C12: Basic | D12: 5066.6667 | E12: 5066.6667
C13: Family | D13: 17916.667 | E13: 17916.667
C14: Standard | D14: 6480 | E14: 6480
C15: Delhi | D15: 52720 | E15: 13180
C16: no | D16: 37573.333 | E16: 12524.444
C17: Family | D17: 36333.333 | E17: 36333.333
C18: Premium | D18: 240 | E18: 240
... C55: Grand Total | D55: 292290 | E55: 8351.1429

Sheet Question.6
A1: Member_ID | B1: City | C1: Gender | D1: Full_Name | E1: Membership_Type | F1: Age_group | G1: Age
A2: =SUBSTITUTE(sheet1!A2,"M","")+0 -> 1 | B2: Bengaluru | C2: Male | D2: Anay Shanker | E2: Basic | F2: =IF(G2<=30,"youth",IF(G2<=45,"Adult","seniors")) -> seniors | G2: 59
A3: =SUBSTITUTE(sheet1!A3,"M","")+0 -> 2 | B3: Pune | C3: Male | D3: Parinaaz Shanker | E3: Basic | F3: =IF(G3<=30,"youth",IF(G3<=45,"Adult","seniors")) -> youth | G3: 27 | I3: Sum of Member_ID | J3: Column Labels | M3: pivot table for Gender-wise count of members per city
A4: =SUBSTITUTE(sheet1!A4,"M","")+0 -> 3 | B4: Hyderabad | C4: Male | D4: Aniruddh Batra | E4: Standard | F4: =IF(G4<=30,"youth",IF(G4<=45,"Adult","seniors")) -> youth | G4: 24 | I4: Row Labels | J4: Male | K4: Female
A5: =SUBSTITUTE(sheet1!A5,"M","")+0 -> 4 | B5: Hyderabad | C5: Female | D5: Madhup Kapur | E5: Standard | F5: =IF(G5<=30,"youth",IF(G5<=45,"Adult","seniors")) -> Adult | G5: 31 | I5: Bengaluru | J5: 6 | K5: 57
A6: =SUBSTITUTE(sheet1!A6,"M","")+0 -> 5 | B6: Bengaluru | C6: Male | D6: Rasha Kakar | E6: Family | F6: =IF(G6<=30,"youth",IF(G6<=45,"Adult","seniors")) -> youth | G6: 19 | I6: Delhi | J6: 23 | K6: 75
A7: =SUBSTITUTE(sheet1!A7,"M","")+0 -> 6 | B7: Mumbai | C7: Male | D7: Ehsaan Batra | E7: Basic | F7: =IF(G7<=30,"youth",IF(G7<=45,"Adult","seniors")) -> Adult | G7: 40 | I7: Hyderabad | J7: 20 | K7: 48
A8: =SUBSTITUTE(sheet1!A8,"M","")+0 -> 7 | B8: Pune | C8: Female | D8: Zara Bains | E8: Basic | F8: =IF(G8<=30,"youth",IF(G8<=45,"Adult","seniors")) -> Adult | G8: 41 | I8: Kolkata | J8: 45 | K8: 43
A9: =SUBSTITUTE(sheet1!A9,"M","")+0 -> 8 | B9: Kolkata | C9: Male | D9: Uthkarsh Baral | E9: Premium | F9: =IF(G9<=30,"youth",IF(G9<=45,"Adult","seniors")) -> Adult | G9: 43 | I9: Mumbai | J9: 167 | K9: 40
A10: =SUBSTITUTE(sheet1!A10,"M","")+0 -> 9 | B10: Kolkata | C10: Male | D10: Kashvi Char | E10: Basic | F10: =IF(G10<=30,"youth",IF(G10<=45,"Adult","seniors")) -> Adult | G10: 42 | I10: Pune | J10: 64 | K10: 42
A11: =SUBSTITUTE(sheet1!A11,"M","")+0 -> 10 | B11: Mumbai | C11: Male | D11: Dhanush Varma | E11: Standard | F11: =IF(G11<=30,"youth",IF(G11<=45,"Adult","seniors")) -> Adult | G11: 37 | I11: Grand Total | J11: 325 | K11: 305
A12: =SUBSTITUTE(sheet1!A12,"M","")+0 -> 11 | B12: Bengaluru | C12: Female | D12: Ishaan Goyal | E12: Standard | F12: =IF(G12<=30,"youth",IF(G12<=45,"Adult","seniors")) -> seniors | G12: 48
A13: =SUBSTITUTE(sheet1!A13,"M","")+0 -> 12 | B13: Kolkata | C13: Male | D13: Mahika Ravi | E13: Standard | F13: =IF(G13<=30,"youth",IF(G13<=45,"Adult","seniors")) -> Adult | G13: 36
A14: =SUBSTITUTE(sheet1!A14,"M","")+0 -> 13 | B14: Kolkata | C14: Female | D14: Purab Reddy | E14: Premium | F14: =IF(G14<=30,"youth",IF(G14<=45,"Adult","seniors")) -> seniors | G14: 48 | I14: Count of Full_Name | J14: Column Labels | M14: pivot table for Age Distribution across Membership Types
A15: =SUBSTITUTE(sheet1!A15,"M","")+0 -> 14 | B15: Mumbai | C15: Male | D15: Tiya Soni | E15: Standard | F15: =IF(G15<=30,"youth",IF(G15<=45,"Adult","seniors")) -> Adult | G15: 39 | I15: Row Labels | J15: youth | K15: seniors | L15: Adult
A16: =SUBSTITUTE(sheet1!A16,"M","")+0 -> 15 | B16: Hyderabad | C16: Female | D16: Zara Dugar | E16: Basic | F16: =IF(G16<=30,"youth",IF(G16<=45,"Adult","seniors")) -> Adult | G16: 44 | I16: Basic | J16: 3 | K16: 2 | L16: 4
A17: =SUBSTITUTE(sheet1!A17,"M","")+0 -> 16 | B17: Kolkata | C17: Male | D17: Lakshit Mander | E17: Family | F17: =IF(G17<=30,"youth",IF(G17<=45,"Adult","seniors")) -> Adult | G17: 39 | I17: Family | J17: 4 | K17: 1 | L17: 2
A18: =SUBSTITUTE(sheet1!A18,"M","")+0 -> 17 | B18: Hyderabad | C18: Male | D18: Neysa Krish | E18: Standard | F18: =IF(G18<=30,"youth",IF(G18<=45,"Adult","seniors")) -> Adult | G18: 35 | I18: Premium | J18: 2 | K18: 4 | L18: 1
A19: =SUBSTITUTE(sheet1!A19,"M","")+0 -> 18 | B19: Delhi | C19: Female | D19: Prerak Boase | E19: Family | F19: =IF(G19<=30,"youth",IF(G19<=45,"Adult","seniors")) -> seniors | G19: 56 | I19: Standard | J19: 4 | K19: 2 | L19: 6
A20: =SUBSTITUTE(sheet1!A20,"M","")+0 -> 19 | B20: Mumbai | C20: Female | D20: Siya Master | E20: Basic | F20: =IF(G20<=30,"youth",IF(G20<=45,"Adult","seniors")) -> youth | G20: 27 | I20: Grand Total | J20: 13 | K20: 9 | L20: 13
A21: =SUBSTITUTE(sheet1!A21,"M","")+0 -> 20 | B21: Mumbai | C21: Male | D21: Madhup Biswas | E21: Family | F21: =IF(G21<=30,"youth",IF(G21<=45,"Adult","seniors")) -> youth | G21: 28
A22: =SUBSTITUTE(sheet1!A22,"M","")+0 -> 21 | B22: Mumbai | C22: Female | D22: Indrans Ratti | E22: Premium | F22: =IF(G22<=30,"youth",IF(G22<=45,"Adult","seniors")) -> seniors | G22: 57
A23: =SUBSTITUTE(sheet1!A23,"M","")+0 -> 22 | B23: Bengaluru | C23: Female | D23: Kimaya Balay | E23: Premium | F23: =IF(G23<=30,"youth",IF(G23<=45,"Adult","seniors")) -> youth | G23: 26
A24: =SUBSTITUTE(sheet1!A24,"M","")+0 -> 23 | B24: Delhi | C24: Male | D24: Eva Dass | E24: Premium | F24: =IF(G24<=30,"youth",IF(G24<=45,"Adult","seniors")) -> seniors | G24: 48
A25: =SUBSTITUTE(sheet1!A25,"M","")+0 -> 24 | B25: Bengaluru | C25: Female | D25: Pihu Wali | E25: Standard | F25: =IF(G25<=30,"youth",IF(G25<=45,"Adult","seniors")) -> youth | G25: 25
A26: =SUBSTITUTE(sheet1!A26,"M","")+0 -> 25 | B26: Mumbai | C26: Male | D26: Tiya Rege | E26: Premium | F26: =IF(G26<=30,"youth",IF(G26<=45,"Adult","seniors")) -> seniors | G26: 53
A27: =SUBSTITUTE(sheet1!A27,"M","")+0 -> 26 | B27: Delhi | C27: Female | D27: Aarav Sen | E27: Standard | F27: =IF(G27<=30,"youth",IF(G27<=45,"Adult","seniors")) -> Adult | G27: 42
A28: =SUBSTITUTE(sheet1!A28,"M","")+0 -> 27 | B28: Mumbai | C28: Male | D28: Dishani Bera | E28: Family | F28: =IF(G28<=30,"youth",IF(G28<=45,"Adult","seniors")) -> youth | G28: 24
A29: =SUBSTITUTE(sheet1!A29,"M","")+0 -> 28 | B29: Pune | C29: Male | D29: Indrans Grover | E29: Standard | F29: =IF(G29<=30,"youth",IF(G29<=45,"Adult","seniors")) -> seniors | G29: 53
A30: =SUBSTITUTE(sheet1!A30,"M","")+0 -> 29 | B30: Hyderabad | C30: Female | D30: Kismat Edwin | E30: Family | F30: =IF(G30<=30,"youth",IF(G30<=45,"Adult","seniors")) -> youth | G30: 29
A31: =SUBSTITUTE(sheet1!A31,"M","")+0 -> 30 | B31: Kolkata | C31: Female | D31: Taran Vyas | E31: Family | F31: =IF(G31<=30,"youth",IF(G31<=45,"Adult","seniors")) -> Adult | G31: 31
A32: =SUBSTITUTE(sheet1!A32,"M","")+0 -> 31 | B32: Delhi | C32: Female | D32: Jiya Baral | E32: Basic | F32: =IF(G32<=30,"youth",IF(G32<=45,"Adult","seniors")) -> seniors | G32: 52
... A36: =SUBSTITUTE(sheet1!A36,"M","")+0 -> 35 | B36: Pune | C36: Female | D36: Oorja Sachar | E36: Standard | F36: =IF(G36<=30,"youth",IF(G36<=45,"Adult","seniors")) -> youth | G36: 27
